Workbook

Sheet Main
F1: LM62460-Q1, LM61480-Q1, LM61495-Q1 Buck Converter Design Tool
B5: About | E5: ="= Input Box" -> = Input Box | W5: Terms Of Use
B8: Step 1: Operating Specifications
B9: Part Number | C9: LM61495-Q1 | P9: IOUT_MAX_TRIM | Q9: =IF(C9="LM61495-Q1",10,IF(C9="LM61480-Q1",8,IF(C9="LM62460-Q1",6,0))) -> 10 | R9: A | S9: ="=10 if LM61495, 8 if LM61480, 6 if LM62440" -> =10 if LM61495, 8 if LM61480, 6 if LM62440
B10: VIN_MIN | C10: 16 | D10: V | P10: IDEALDUTYCYCLE | Q10: =C13/C11 -> 0.72727273 | R10: % | S10: ="=VOUT/VIN_NOM" -> =VOUT/VIN_NOM
B11: VIN_NOM | C11: 22 | D11: V | P11: PLOSS | Q11: =(C14*C14)*(C20/1000+Q10*Q71+(1-Q10)*Q72) -> 2.6818182 | R11: W | S11: ="=IOUT_MAX^2*(LDCR+IDEALDUTYCYCLE*RDSON_HS+IDEALDUTYCYCLE*RDSON_LS" -> =IOUT_MAX^2*(LDCR+IDEALDUTYCYCLE*RDSON_HS+IDEALDUTYCYCLE*RDSON_LS
B12: VIN_MAX | C12: 26 | D12: V | P12: POUT | Q12: =C13*C14 -> 160 | R12: W | S12: ="=VOUT*IOUT_MAX" -> =VOUT*IOUT_MAX
B13: VOUT | C13: 16 | D13: V | P13: PIN | Q13: =Q12+Q11 -> 162.68182 | R13: W | S13: ="=POUT+PLOSS" -> =POUT+PLOSS
B14: IOUT_MAX | C14: 10 | D14: A | P14: EFFICIENCY | Q14: =Q12/Q13 -> 0.98351495 | R14: % | S14: ="=POUT/PIN" -> =POUT/PIN
B15: FSW_SELECTED | C15: 400 | D15: kHz | P15: DUTYCYCLE | Q15: =C13/(C11*Q14) -> 0.73946281 | R15: % | S15: ="=VOUT/(VIN*EFFICIENCY)" -> =VOUT/(VIN*EFFICIENCY)
P16: TON | Q16: =(1/(C15*1000))*Q15 -> 1.848657e-06 | R16: s | S16: ="=(1/FSW_SELECTED)*DUTYCYCLE" -> =(1/FSW_SELECTED)*DUTYCYCLE
B17: Step 2: Buck Inductor | P17: TOFF | Q17: =(1/(C15*1000))*(1-Q15) -> 6.5134298e-07 | R17: s | S17: ="=(1/FSW_SELECTED)*(1-DUTYCYCLE)" -> =(1/FSW_SELECTED)*(1-DUTYCYCLE)
B18: LRECOMMENDED | C18: =Q19*1000000 -> 3.6 | D18: μH | P18: LRECOMMENDED | Q18: =(C11-C13)*(Q16/(0.3*C14)) -> 3.697314e-06 | R18: H | S18: ="=(VIN-VOUT)*(TON/(0.3*IOUT_MAX))" -> =(VIN-VOUT)*(TON/(0.3*IOUT_MAX))
B19: LCHOSEN | C19: 3.5 | D19: μH | P19: LRECOMMENDED_STD | Q19: =IF(ISNUMBER(Q18),INDEX(LstdVal!$A$1:$A$769,MATCH(Q18,LstdVal!$A$1:$A$769)),Q18) -> 3.6e-06 | R19: H | S19: See Standard Values Calculator sheet
B20: LDCR | C20: 9 | D20: mΩ | P20: ΔILPEAK-PEAK | Q20: =(Q56-(Q71+Q62)*Q59-Q58)*Q15/(Q60*Q61) -> 3.0159519 | R20: A PK-PK | S20: ="=(VIN_NOM-(RDSON_HS+LDCR)*IOUT_MAX-VOUT)*DUTYCYCLE/(FSW_SELECTED*LCHOSEN)" -> =(VIN_NOM-(RDSON_HS+LDCR)*IOUT_MAX-VOUT)*DUTYCYCLE/(FSW_SELECTED*LCHOSEN)
B21: ΔILPEAK-PEAK | C21: =Q20 -> 3.0159519 | D21: A PK-PK | P21: %RIPPLE_CURRENT | Q21: =Q20/C14 -> 0.30159519 | R21: % | S21: ="=ΔILPEAK-PEAK/IOUT_MAX" -> =ΔILPEAK-PEAK/IOUT_MAX
B22: Ripple Current | C22: =Q21*100 -> 30.159519 | D22: % | P22: COUT_MIN_TRANSIENT | Q22: =(((Q63^2)*Q61)/((Q56-Q58)*(Q58*0.025))) -> 1.3125e-05 | R22: F | S22: ="=((ISTEP_MAX^2)*LCHOSEN)/((VIN_NOM-VOUT)*(VOUT*.025))" -> =((ISTEP_MAX^2)*LCHOSEN)/((VIN_NOM-VOUT)*(VOUT*.025)) | X22: Necessary output cap to meet droop spec on a transient
P23: COUT_MIN_RIPPLE_W/OESR | Q23: =Q20*1/(8*Q60*Q58*0.02) -> 2.9452655e-06 | R23: F | S23: ="=ΔILPEAK-PEAK*1/(8*FSW_SELECTED*VOUT*0.02)" -> =ΔILPEAK-PEAK*1/(8*FSW_SELECTED*VOUT*0.02) | X23: COUT for 2% ripple (not considering ESR of COUT)
B24: Step 3: Output Capacitors | P24: COUT_MIN_RIPPLE_W/ESR | R24: F
B25: ISTEP_MAX | C25: 3 | D25: A | P25: COUT_STABILITY_CERAMIC_ONLY | R25: F
B26: COUT_MIN (After Derating) | C26: =Q33 -> 59.537207 | D26: μF | P26: COUT_STABILITY_CERAMIC_w/Ecap | R26: F
B27: COUT_CHOSEN | C27: 80 | D27: μF | P27: COUT_STABILITY_ECAP_w/ceramic | R27: F
B28: Optional COUT_HF | C28: 2.2 | D28: uF
B29: COUT_BULK (suggested) | C29: =IF(((150*(C25/Q44)/(SQRT(C15)/SQRT(400)))*(SQRT(5)/SQRT(C13)))<22,"-",((150*(C25/Q44)/(SQRT(C15)/SQRT(400)))*(SQRT(5)/SQRT(C13)))) -> 25.155765 | D29: μF
B30: Optional COUT_BULK | C30: 68 | D30: uF | P30: CIN_MIN_HF | Q30: 2x0.47 | R30: uF | S30: 2x0.47uF X7R 50V AEC-Q200 rated | X30: Min high-frequency ceramic cap for input.
P31: CIN_MIN | Q31: 2x10 | R31: uF | S31: 2x10uF X7R 50V AEC-Q200 rated | X31: Min ceramic cap for input.
B32: Step 4: Input Capacitors | P32: CIN_BULK | Q32: =IF(Q63>=3, 10*Q63,"None") -> 30 | R32: uF | S32: if ISTEP_MAX >= 3A, add 10uF*ISTEP, else "None"
B33: CIN_MIN_HF | C33: =Q30 -> 2x0.47 | D33: μF | P33: COUT_MIN_STABILITY | Q33: =1776/(MIN(C13, 9)*POWER(C15,0.2)) -> 59.537207 | R33: uF | S33: ="1776 / (min(VOUT, 9)*(fsw_kHz)^0.2)" -> 1776 / (min(VOUT, 9)*(fsw_kHz)^0.2) | X33: Equation from Marc Davis-Marsh
B34: CIN_MIN | C34: =Q31 -> 2x10 | D34: μF
B35: CIN_BULK | C35: =Q32 -> 30 | D35: μF | P35: REN/UVLO_BOTTOM | Q35: =-(C41*Q73)/(Q73-C40) -> 22.608821 | R35: kΩ
P36: REN/UVLO_BOTTOM_std_val | Q36: =INDEX(RstdVal!$A$1:$A$769,MATCH(Q35,RstdVal!$A$1:$A$769)) -> 22.6 | R36: kΩ
B37: Step 5: Feedback, UVLO, RT... | P37: RFBB | Q37: =Q66*(1/(C13-1)) -> 6666.6667 | R37: Ω
B38: RFB_TOP | C38: 100 | D38: kΩ | P38: RFBB_std_val | Q38: =INDEX(RstdVal!$A$1:$A$769,MATCH(Q37,RstdVal!$A$1:$A$769))/1000 -> 6.65 | R38: kΩ
B39: RFB_BOTTOM | C39: =Q38 -> 6.65 | D39: kΩ | P39: RUVLO_BOTTOM | Q39: =-(Q68*Q73)/(Q73-C40) -> 22608.821 | R39: Ω
B40: VUVLO | C40: 5 | D40: V | P40: RUVLO_BOTTOM_std_val | Q40: =INDEX(RstdVal!$A$1:$A$769,MATCH(Q39,RstdVal!$A$1:$A$769))/1000 -> 22.6 | R40: kΩ
B41: REN/UVLO_TOP | C41: 100 | D41: kΩ | P41: RT | Q41: =IF(C15=400,"Short to VCC",IF(C15=2200,"Short to GND",((16400/(C15))-0.633))) -> Short to VCC | R41: kΩ | S41: ="Short to GND for 400kHz, short to VCC for 2.2MHz, or =(16400/(freq(kHz) ) – 0.633) for 200kHz to 2.2MHz" -> Short to GND for 400kHz, short to VCC for 2.2MHz, or =(16400/(freq(kHz) ) – 0.633) for 200kHz to 2.2MHz
B42: REN/UVLO_BOTTOM | C42: =Q36 -> 22.6 | D42: kΩ | P42: RT_std_val | Q42: =IF(ISNUMBER(Q41),INDEX(RstdVal!$A$1:$A$769,MATCH(Q41,RstdVal!$A$1:$A$769)),Q41) -> Short to VCC | R42: kΩ
B43: RT | C43: =Q42 -> Short to VCC | D43: kΩ
B44: RBOOT | C44: 0 | D44: Ω | O44: RSPSP calculations | P44: IOUT_TRIM | Q44: =IF(C9=Q82, 6, IF(C9=Q83,8,IF(C9=Q84,10,""))) -> 10 | R44: A | S44: 6A, 8A, or 10A based on part number selection. Used in spread spectrum resistor calculation
B45: CBOOT | C45: 0.1 | D45: μF | P45: ΔILPEAK-PEAK-1% | Q45: =Q20/1.01 -> 2.986091 | R45: A | S45: ΔILPEAK-PEAK / 1.01 For RSPSP calc, 1% spread
...

Sheet RstdVal
A1: 1 | C1: =INDEX(A1:A769,MATCH(12,A1:A769)) -> 11.8
A2: 1.02
A3: 1.05
A4: 1.07
A5: 1.1
A6: 1.13
A7: 1.15
A8: 1.18
A9: 1.21
A10: 1.24
A11: 1.27
A12: 1.3
A13: 1.33
... A96: 9.76
A97: =A1*10 -> 10
A98: =A2*10 -> 10.2
A99: =A3*10 -> 10.5
A100: =A4*10 -> 10.7
A101: =A5*10 -> 11
A102: =A6*10 -> 11.3
A103: =A7*10 -> 11.5
A104: =A8*10 -> 11.8
A105: =A9*10 -> 12.1
A106: =A10*10 -> 12.4
A107: =A11*10 -> 12.7
A108: =A12*10 -> 13
... A769: =A673*10 -> 100000000

Sheet LstdVal
A1: 1e-09
A2: 1.1e-09
A3: 1.2e-09
A4: 1.3e-09
A5: 1.5e-09
A6: 1.6e-09
A7: 1.8e-09
A8: 2e-09
A9: 2.2e-09
A10: 2.4e-09
A11: 2.7e-09
A12: 3e-09
... A226: 1
